{
  "nbformat": 4,
  "nbformat_minor": 0,
  "metadata": {
    "colab": {
      "provenance": []
    },
    "kernelspec": {
      "name": "python3",
      "display_name": "Python 3"
    },
    "language_info": {
      "name": "python"
    }
  },
  "cells": [
    {
      "cell_type": "code",
      "source": [
        "import os # work with system    \n",
        "import cv2 # work with images\n",
        "import numpy as np # arrays and numerical analysis  \n",
        "import matplotlib.pyplot as plt # for data plots"
      ],
      "metadata": {
        "id": "7GWaFRPlWeVm"
      },
      "execution_count": 20,
      "outputs": []
    },
    {
      "cell_type": "code",
      "execution_count": 21,
      "metadata": {
        "colab": {
          "base_uri": "https://localhost:8080/"
        },
        "id": "hmYTZjL8VKe6",
        "outputId": "b1aa9b1f-626c-476c-c837-7d830d3b812e"
      },
      "outputs": [
        {
          "output_type": "stream",
          "name": "stdout",
          "text": [
            "Drive already mounted at /content/drive; to attempt to forcibly remount, call drive.mount(\"/content/drive\", force_remount=True).\n"
          ]
        }
      ],
      "source": [
        "### To gain authorization to google drive\n",
        "from google.colab import drive\n",
        "drive.mount('/content/drive')"
      ]
    },
    {
      "cell_type": "code",
      "source": [
        "# check current wd\n",
        "os.getcwd()\n",
        "# set working directory in data folder\n",
        "# this will not work for you, the path is a place holder for when you \n",
        "os.chdir(\"drive/Shareddrives/STAT_626/Data\")\n",
        "# 06/11 as of now for some reason the path is not recognized i am unsure as to why. will look at this monday.\n",
        "# if you run this again and it shoots an error, hash the chdir function. It could be that the wd has already changed.\n"
      ],
      "metadata": {
        "colab": {
          "base_uri": "https://localhost:8080/",
          "height": 235
        },
        "id": "d9o7W-tKVaDg",
        "outputId": "fe933536-1f9c-421a-c99e-77d1e31edee5"
      },
      "execution_count": 28,
      "outputs": [
        {
          "output_type": "error",
          "ename": "FileNotFoundError",
          "evalue": "ignored",
          "traceback": [
            "\u001b[0;31m---------------------------------------------------------------------------\u001b[0m",
            "\u001b[0;31mFileNotFoundError\u001b[0m                         Traceback (most recent call last)",
            "\u001b[0;32m<ipython-input-28-003a46a9c404>\u001b[0m in \u001b[0;36m<cell line: 5>\u001b[0;34m()\u001b[0m\n\u001b[1;32m      3\u001b[0m \u001b[0;31m# set working directory in data folder\u001b[0m\u001b[0;34m\u001b[0m\u001b[0;34m\u001b[0m\u001b[0m\n\u001b[1;32m      4\u001b[0m \u001b[0;31m# this will not work for you, the path is a place holder for when you\u001b[0m\u001b[0;34m\u001b[0m\u001b[0;34m\u001b[0m\u001b[0m\n\u001b[0;32m----> 5\u001b[0;31m \u001b[0mos\u001b[0m\u001b[0;34m.\u001b[0m\u001b[0mchdir\u001b[0m\u001b[0;34m(\u001b[0m\u001b[0;34m\"drive/Shareddrives/STAT_626/Data\"\u001b[0m\u001b[0;34m)\u001b[0m\u001b[0;34m\u001b[0m\u001b[0;34m\u001b[0m\u001b[0m\n\u001b[0m\u001b[1;32m      6\u001b[0m \u001b[0;31m# 06/11 as of now for some reason the path is not recognized i am unsure as to why. will look at this monday.\u001b[0m\u001b[0;34m\u001b[0m\u001b[0;34m\u001b[0m\u001b[0m\n\u001b[1;32m      7\u001b[0m \u001b[0;31m# if you run this again and it shoots an error, hash the chdir function. It could be that the wd has already changed.\u001b[0m\u001b[0;34m\u001b[0m\u001b[0;34m\u001b[0m\u001b[0m\n",
            "\u001b[0;31mFileNotFoundError\u001b[0m: [Errno 2] No such file or directory: 'drive/Shareddrives/STAT_626/Data'"
          ]
        }
      ]
    }
  ]
}